<robot name="shadow_right">  
  <link name="world"/>

  <link name="virtual_link_x" />
  <joint name="virtual_joint_x" type="prismatic">
    <parent link="world" />
    <child link="virtual_link_x" />

    <origin rpy="0 0 0" xyz="0 0 0" />
    <axis xyz="1 0 0" />
    <limit effort="300" lower="-10" upper="10" velocity="2" />
  </joint>

  <link name="virtual_link_y" />
  <joint name="virtual_joint_y" type="prismatic">
    <parent link="virtual_link_x" />
    <child link="virtual_link_y" />

    <origin rpy="0 0 0" xyz="0 0 0" />
    <axis xyz="0 1 0" />
    <limit effort="300" lower="-10" upper="10" velocity="2" />
  </joint>

  <link name="virtual_link_z" />
  <joint name="virtual_joint_z" type="prismatic">
    <parent link="virtual_link_y" />
    <child link="virtual_link_z" />

    <origin rpy="0 0 0" xyz="0 0 0" />
    <axis xyz="0 0 1" />
    <limit effort="300" lower="-10" upper="10" velocity="2" />
  </joint>

  <link name="virtual_link_roll" />
  <joint name="virtual_joint_roll" type="revolute">
    <parent link="virtual_link_z" />
    <child link="virtual_link_roll" />

    <origin rpy="0 0 0" xyz="0 0 0" />
    <axis xyz="1 0 0" />
    <limit effort="100" velocity="100" lower="-6.283185" upper="6.283185" />
  </joint>

  <link name="virtual_link_pitch" />
  <joint name="virtual_joint_pitch" type="revolute">
    <parent link="virtual_link_roll" />
    <child link="virtual_link_pitch" />

    <origin rpy="0 0 0" xyz="0 0 0" />
    <axis xyz="0 1 0" />
    <limit effort="100" velocity="100" lower="-6.283185" upper="6.283185" />
  </joint>

  <link name="virtual_link_yaw" />
  <joint name="virtual_joint_yaw" type="revolute">
    <parent link="virtual_link_pitch" />
    <child link="virtual_link_yaw" />

    <origin rpy="0 0 0" xyz="0 0 0" />
    <axis xyz="0 0 1" />
    <limit effort="100" velocity="100" lower="-6.283185" upper="6.283185" />
  </joint>
  
  <joint name="virtual_robot" type="fixed">
    <parent link="virtual_link_yaw" />
    <child link="cylinder_link" />
    <origin rpy="0 0 1.57079" xyz="0 0 0" />
  </joint>

  <link name="cylinder_link">
    <inertial>
      <origin rpy="0 0 0" xyz="0 0 0"/>
      <mass value="3.0"/>
      <inertia ixx="1e-3" ixy="0" ixz="0" iyy="1e-3" iyz="0" izz="1e-3"/>
    </inertial>

    <visual>`
      <origin rpy="0 0 0" xyz="0 0 0"/>
      <geometry>
        <mesh filename="meshes/visual/cylinder_factory/cylinder_r_40_h_150.obj" scale="0.001 0.001 0.001"/>
      </geometry>
    </visual>

    <collision>
      <origin rpy="0 0 0" xyz="0 0 0"/>
      <geometry>
        <cylinder radius="0.04" length="0.15"/>
      </geometry>
    </collision>
  </link>
  
  <joint name="cylinder" type="fixed">
    <parent link="cylinder_link"/>
    <child link="forearm"/>
    <origin rpy="0 0 0" xyz="0 0 0.15"/>
  </joint>

  <link name="forearm">
    <inertial>
      <origin rpy="0 0 0" xyz="0 0 0.09"/>
      <mass value="3.0"/>
      <inertia ixx="0.0138" ixy="0.0" ixz="0.0" iyy="0.0138" iyz="0.0" izz="0.00744"/>
    </inertial>
    <visual>
      <origin rpy="0 0 0" xyz="0 0 0.0"/>
      <geometry name="forearm_visual">
        <mesh filename="meshes/visual/forearm_E3M5.obj" scale="0.001 0.001 0.001"/>
      </geometry>
    </visual>
    <collision>
      <origin rpy="0 0 0" xyz="0 0 0.0"/>
      <geometry name="forearm_collision">
        <mesh filename="meshes/collision/forearm_E3M5.obj" scale="0.001 0.001 0.001"/>
      </geometry>
    </collision>
    <!-- wrist mount -->
    <collision>
      <origin rpy="0 0.785395 0" xyz="0 -0.01 0.165"/>
      <geometry>
        <box size="0.07 0.07 0.07"/>
      </geometry>
    </collision>
  </link>
  <link name="wrist">
    <inertial>
      <origin rpy="0 0 0" xyz="0 0 0.029"/>
      <mass value="0.1"/>
      <inertia ixx="0.000035" ixy="0.0" ixz="0.0" iyy="0.000064" iyz="0.0" izz="0.0000438"/>
    </inertial>
    <visual>
      <origin rpy="0 0 0" xyz="0 0 0"/>
      <geometry name="wrist_visual">
        <mesh filename="meshes/visual/wrist_E3M5.obj" scale="0.001 0.001 0.001"/>
      </geometry>
    </visual>
    <collision>
      <origin rpy="1.5708 1.5708 0" xyz="0 0 0"/>
      <geometry name="wrist_collision_geom">
        <cylinder length="0.030" radius="0.0135"/>
      </geometry>
    </collision>
    <collision>
      <origin rpy="0 1.5708 0" xyz="-0.026 0 0.034"/>
      <geometry>
        <cylinder length="0.010" radius="0.011"/>
      </geometry>
    </collision>
    <collision>
      <origin rpy="0 1.5708 0" xyz="0.031 0 0.034"/>
      <geometry>
        <cylinder length="0.010" radius="0.011"/>
      </geometry>
    </collision>
    <collision>
      <origin rpy="0 0.7854 0" xyz="-0.021 0 0.011"/>
      <geometry>
        <box size="0.027 0.018 0.010"/>
      </geometry>
    </collision>
    <collision>
      <origin rpy="0 -0.7854 0" xyz="0.026 0 0.010"/>
      <geometry>
        <box size="0.027 0.018 0.010"/>
      </geometry>
    </collision>
  </link>
  <joint name="WRJ2" type="fixed">
    <parent link="forearm"/>
    <child link="wrist"/>
    <origin rpy="0 0 0" xyz="0 -0.010 0.21301"/>
  </joint>

  <link name="palm">
    <inertial>
      <origin rpy="0.1679250647072471 0.04643268296615992 1.542522903299366" xyz="0.006 0 0.036"/>
      <mass value="4.0"/>
      <inertia ixx="0.01" ixy="0.0" ixz="0.0" iyy="0.01" iyz="0.0" izz="0.0075"/>
    </inertial>
    <visual>
      <origin rpy="0 0 0" xyz="0 0 0"/>
      <geometry name="palm_visual">
        <mesh filename="meshes/visual/palm_E3M5.obj" scale="0.001 0.001 0.001"/>
      </geometry>
    </visual>
    <collision>
      <origin rpy="0 0 0" xyz="0.011 0.0085 0.042"/>
      <geometry name="palm_collision_geom">
        <box size="0.062 0.007 0.090"/>
      </geometry>
    </collision>
    <collision>
      <origin rpy="0 0 0" xyz="-0.002 -0.0035 0.042" />
      <geometry>
        <box size="0.036 0.017 0.090" />
      </geometry>
    </collision>
    
    <collision>
      <origin rpy="0 0 0" xyz="0.029 -0.0035 0.082" />
      <geometry>
        <box size="0.026 0.017 0.010" />
      </geometry>
    </collision>
    <collision>
      <origin rpy="0.2 0 0.25" xyz="0.0265 -0.001 0.070" />
      <geometry>
        <box size="0.026 0.014 0.018" />
      </geometry>
    </collision>
    
    <collision>
      <origin rpy="0 0 0" xyz="0.0315 -0.0085 0.005" />
      <geometry>
        <box size="0.021 0.027 0.016" />
      </geometry>
    </collision>
    
    <collision>
      <origin rpy="0 0 -0.48" xyz="0.0125 -0.015 0.013" />
      <geometry>
        <box size="0.022 0.005 0.032" />
      </geometry>
    </collision>
    
    <collision>
      <origin rpy="0 0 0" xyz="0.011 0 0.089" />
      <geometry>
        <box size="0.018 0.024 0.004" />
      </geometry>
    </collision>
    
    <collision>
      <origin rpy="0 0 0" xyz="-0.03 0 0.013" />
      <geometry>
        <box size="0.020 0.024 0.032" />
      </geometry>
    </collision>
  </link>
  <joint name="ee_fixed_joint" type="fixed">
    <parent link="palm" />
    <child link="ee_link" />
    <origin rpy="0.0 0.0 -1.57079" xyz="0.0 0.0 0.0" />
  </joint>
  <link name="ee_link" />

   <joint name="WRJ1" type="fixed">
    <parent link="wrist"/>
    <child link="palm"/>
    <origin rpy="0 0 0" xyz="0 0 0.034"/>
  </joint>
  
  <link name="imu" />
  <joint name="palm_to_imu" type="fixed">
    <parent link="palm" />
    <child link="imu" />
    <origin rpy="-1.5707963 3.141592 0.0" xyz="0.01785 0.00765 0.049125" />
  </joint>
  <link name="ffknuckle">
    <inertial>
      <origin rpy="2.047545928289858 0.011364244606314553 0.007128520828102848" xyz="0 0 0" />
      <mass value="0.008" />
      <inertia ixx="1e-05" ixy="0.0" ixz="0.0" iyy="1e-05" iyz="0.0" izz="1e-05" />
    </inertial>
    <visual>
      <origin rpy="0 0 0" xyz="0 0 0.0005" />
      <geometry name="ffknuckle_visual">
        <mesh filename="meshes/visual/f_knuckle_E3M5.obj" scale="0.001 0.001 0.001" />
      </geometry>
    </visual>
    <collision>
      <geometry name="ffknuckle_visual">
        <mesh filename="meshes/collision/f_knuckle_E3M5.obj" />
      </geometry>
    </collision>
  </link>
  <joint name="FFJ4" type="revolute">
    <parent link="palm" />
    <child link="ffknuckle" />
    <origin rpy="0 0 0" xyz="0.033 0 0.095" />
    <axis xyz="0 -1 0" />
    <limit effort="2" lower="-0.349065850399" upper="0.349065850399" velocity="2.0" />
    <dynamics damping="0.1" />
  </joint>
  <link name="ffproximal">
    <inertial>
      <mass value="0.014" />
      <origin xyz="0 0 0.023" rpy="0.0 0.01131224126368007 1.570526236591334" />
      <inertia ixx="1e-05" ixy="0.0" ixz="0.0" iyy="1e-05" iyz="0.0" izz="1e-05" />
    </inertial>
    <visual>
      <origin rpy="0 0 0" xyz="0 0 0" />
      <geometry name="ffproximal_visual">
        <mesh filename="meshes/visual/f_proximal_E3M5.obj" scale="0.001 0.001 0.001" />
      </geometry>
    </visual>
    <collision>
      <origin rpy="0 0 0" xyz="0 0 0.025" />
      <geometry name="ffproximal_collision_geom">
        <cylinder length="0.040" radius="0.007" />
      </geometry>
    </collision>
  </link>
  <joint name="FFJ3" type="revolute">
    <parent link="ffknuckle" />
    <child link="ffproximal" />
    <origin rpy="0 0 0" xyz="0 0 0" />
    <axis xyz="1 0 0" />
    <limit effort="2" lower="-0.261799387799" upper="1.57079632679" velocity="2.0" />
    <dynamics damping="0.1" />
  </joint>
  <link name="ffmiddle">
    <inertial>
      <origin rpy="0.0 0.0 1.570494235572534" xyz="0 0 0.011" />
      <mass value="0.012" />
      <inertia ixx="1e-05" ixy="0.0" ixz="0.0" iyy="1e-05" iyz="0.0" izz="1e-05" />
    </inertial>
    <visual>
      <origin rpy="0 0 0" xyz="0 0 0" />
      <geometry name="ffmiddle_visual">
        <mesh filename="meshes/visual/f_middle_E3M5.obj" scale="0.001 0.001 0.001" />
      </geometry>
    </visual>
    <collision>
      <origin rpy="0 0 0" xyz="0 0 0.0125" />
      <geometry name="ffmiddle_collision_geom">
        <cylinder length="0.025" radius="0.007" />
      </geometry>
    </collision>
    <collision>
      <origin rpy="0 0 0" xyz="0 0 0.0" />
      <geometry>
        <sphere radius="0.007" />
      </geometry>
    </collision>
    <collision>
      <origin rpy="0 0 0" xyz="0 0 0.025" />
      <geometry>
        <sphere radius="0.007" />
      </geometry>
    </collision>
  </link>
  <joint name="FFJ2" type="revolute">
    <parent link="ffproximal" />
    <child link="ffmiddle" />
    <origin rpy="0 0 0" xyz="0 0 0.045" />
    <axis xyz="1 0 0" />
    <limit effort="2" lower="0" upper="1.57079632679" velocity="2.0" />
    <dynamics damping="0.1" />
  </joint>
  <link name="ffdistal">
    
    <inertial>
      <mass value="0.01" />
      <origin xyz="0 0 0.015" rpy="0.0 0.008484101780550713 1.5705122358934482" />
      <inertia ixx="1e-05" ixy="0.0" ixz="0.0" iyy="1e-05" iyz="0.0" izz="1e-05" />
    </inertial>
    <visual>
      <origin rpy="0 0 0" xyz="0 0 0" />
      <geometry name="ffdistal_visual">
        <mesh filename="meshes/visual/f_distal_pst.obj" scale="0.001 0.001 0.001" />
      </geometry>
    </visual>
    <collision>
      <origin rpy="0 0 0" xyz="0 0 0" />
      <geometry name="ffdistal_collision_geom">
        <mesh filename="meshes/visual/f_distal_pst.obj" scale="0.001 0.001 0.001" />
      </geometry>
    </collision>
  </link>
  <joint name="FFJ1" type="revolute">
    <parent link="ffmiddle" />
    <child link="ffdistal" />
    <origin rpy="0 0 0" xyz="0 0 0.025" />
    <axis xyz="1 0 0" />
    
    <limit effort="2" lower="0" upper="1.57079632679" velocity="2.0" />
    <dynamics damping="0.1" />
  </joint>
  <link name="fftip">
    <inertial>
      <mass value="0.001" />
      <inertia ixx="0.0" ixy="0.0" ixz="0.0" iyy="0.0" iyz="0.0" izz="0.0" />
    </inertial>
  </link>
  <joint name="FFtip" type="fixed">
    <parent link="ffdistal" />
    <child link="fftip" />
    <origin rpy="0 0 0" xyz="0 0 0.026" />
  </joint>
  <link name="mfknuckle">
    <inertial>
      <origin rpy="2.047545928289858 0.011364244606314553 0.007128520828102848" xyz="0 0 0" />
      <mass value="0.008" />
      <inertia ixx="1e-05" ixy="0.0" ixz="0.0" iyy="1e-05" iyz="0.0" izz="1e-05" />
    </inertial>
    <visual>
      <origin rpy="0 0 0" xyz="0 0 0.0005" />
      <geometry name="mfknuckle_visual">
        <mesh filename="meshes/visual/f_knuckle_E3M5.obj" scale="0.001 0.001 0.001" />
      </geometry>
    </visual>
    <collision>
      <geometry name="ffknuckle_visual">
        <mesh filename="meshes/collision/f_knuckle_E3M5.obj" />
      </geometry>
    </collision>
  </link>
  <joint name="MFJ4" type="revolute">
    <parent link="palm" />
    <child link="mfknuckle" />
    
    <origin rpy="0 0 0" xyz="0.011 0 0.099" />
    <axis xyz="0 -1 0" />
    <limit effort="2" lower="-0.349065850399" upper="0.349065850399" velocity="2.0" />
    <dynamics damping="0.1" />
  </joint>
  <link name="mfproximal">
    <inertial>
      <mass value="0.014" />
      <origin xyz="0 0 0.023" rpy="0.0 0.01131224126368007 1.570526236591334" />
      <inertia ixx="1e-05" ixy="0.0" ixz="0.0" iyy="1e-05" iyz="0.0" izz="1e-05" />
    </inertial>
    <visual>
      <origin rpy="0 0 0" xyz="0 0 0" />
      <geometry name="mfproximal_visual">
        <mesh filename="meshes/visual/f_proximal_E3M5.obj" scale="0.001 0.001 0.001" />
      </geometry>
    </visual>
    <collision>
      <origin rpy="0 0 0" xyz="0 0 0.025" />
      <geometry name="mfproximal_collision_geom">
        <cylinder length="0.040" radius="0.007" />
      </geometry>
    </collision>
  </link>
  <joint name="MFJ3" type="revolute">
    <parent link="mfknuckle" />
    <child link="mfproximal" />
    <origin rpy="0 0 0" xyz="0 0 0" />
    <axis xyz="1 0 0" />
    <limit effort="2" lower="-0.261799387799" upper="1.57079632679" velocity="2.0" />
    <dynamics damping="0.1" />
  </joint>
  <link name="mfmiddle">
    <inertial>
      <origin rpy="0.0 0.0 1.570494235572534" xyz="0 0 0.012" />
      <mass value="0.012" />
      <inertia ixx="1e-05" ixy="0.0" ixz="0.0" iyy="1e-05" iyz="0.0" izz="1e-05" />
    </inertial>
    <visual>
      <origin rpy="0 0 0" xyz="0 0 0" />
      <geometry name="mfmiddle_visual">
        <mesh filename="meshes/visual/f_middle_E3M5.obj" scale="0.001 0.001 0.001" />
      </geometry>
    </visual>
    <collision>
      <origin rpy="0 0 0" xyz="0 0 0.0125" />
      <geometry name="mfmiddle_collision_geom">
        <cylinder length="0.025" radius="0.007" />
      </geometry>
    </collision>
    <collision>
      <origin rpy="0 0 0" xyz="0 0 0.0" />
      <geometry>
        <sphere radius="0.007" />
      </geometry>
    </collision>
    <collision>
      <origin rpy="0 0 0" xyz="0 0 0.025" />
      <geometry>
        <sphere radius="0.007" />
      </geometry>
    </collision>
  </link>
  <joint name="MFJ2" type="revolute">
    <parent link="mfproximal" />
    <child link="mfmiddle" />
    <origin rpy="0 0 0" xyz="0 0 0.045" />
    <axis xyz="1 0 0" />
    <limit effort="2" lower="0" upper="1.57079632679" velocity="2.0" />
    <dynamics damping="0.1" />
  </joint>
  <link name="mfdistal">
    
    <inertial>
      <mass value="0.01" />
      <origin xyz="0 0 0.015" rpy="0.0 0.008484101780550713 1.5705122358934482" />
      <inertia ixx="1e-05" ixy="0.0" ixz="0.0" iyy="1e-05" iyz="0.0" izz="1e-05" />
    </inertial>
    <visual>
      <origin rpy="0 0 0" xyz="0 0 0" />
      <geometry name="mfdistal_visual">
        <mesh filename="meshes/visual/f_distal_pst.obj" scale="0.001 0.001 0.001" />
      </geometry>
    </visual>
    <collision>
      <origin rpy="0 0 0" xyz="0 0 0" />
      <geometry name="mfdistal_collision_geom">
        <mesh filename="meshes/collision/f_distal_pst.obj" scale="0.001 0.001 0.001" />
      </geometry>
    </collision>
  </link>
  <joint name="MFJ1" type="revolute">
    <parent link="mfmiddle" />
    <child link="mfdistal" />
    <origin rpy="0 0 0" xyz="0 0 0.025" />
    <axis xyz="1 0 0" />
    
    <limit effort="2" lower="0" upper="1.57079632679" velocity="2.0" />
    <dynamics damping="0.1" />
  </joint>
  <link name="mftip">
    <inertial>
      <mass value="0.001" />
      <inertia ixx="0.0" ixy="0.0" ixz="0.0" iyy="0.0" iyz="0.0" izz="0.0" />
    </inertial>
  </link>
  <joint name="MFtip" type="fixed">
    <parent link="mfdistal" />
    <child link="mftip" />
    <origin rpy="0 0 0" xyz="0 0 0.026" />
  </joint>
  <link name="rfknuckle">
    <inertial>
      <origin rpy="2.047545928289858 0.011364244606314553 0.007128520828102848" xyz="0 0 0" />
      <mass value="0.008" />
      <inertia ixx="1e-05" ixy="0.0" ixz="0.0" iyy="1e-05" iyz="0.0" izz="1e-05" />
    </inertial>
    <visual>
      <origin rpy="0 0 0" xyz="0 0 0.0005" />
      <geometry name="rfknuckle_visual">
        <mesh filename="meshes/visual/f_knuckle_E3M5.obj" scale="0.001 0.001 0.001" />
      </geometry>
    </visual>
    <collision>
      <geometry name="ffknuckle_visual">
        <mesh filename="meshes/collision/f_knuckle_E3M5.obj" />
      </geometry>
    </collision>
  </link>
  <joint name="RFJ4" type="revolute">
    <parent link="palm" />
    <child link="rfknuckle" />
    
    <origin rpy="0 0 0" xyz="-0.011 0 0.095" />
    <axis xyz="0 1 0" />
    <limit effort="2" lower="-0.349065850399" upper="0.349065850399" velocity="2.0" />
    <dynamics damping="0.1" />
  </joint>
  <link name="rfproximal">
    <inertial>
      <mass value="0.014" />
      <origin xyz="0 0 0.023" rpy="0.0 0.01131224126368007 1.570526236591334" />
      <inertia ixx="1e-05" ixy="0.0" ixz="0.0" iyy="1e-05" iyz="0.0" izz="1e-05" />
    </inertial>
    <visual>
      <origin rpy="0 0 0" xyz="0 0 0" />
      <geometry name="rfproximal_visual">
        <mesh filename="meshes/visual/f_proximal_E3M5.obj" scale="0.001 0.001 0.001" />
      </geometry>
    </visual>
    <collision>
      <origin rpy="0 0 0" xyz="0 0 0.025" />
      <geometry name="rfproximal_collision_geom">
        <cylinder length="0.040" radius="0.007" />
      </geometry>
    </collision>
  </link>
  <joint name="RFJ3" type="revolute">
    <parent link="rfknuckle" />
    <child link="rfproximal" />
    <origin rpy="0 0 0" xyz="0 0 0" />
    <axis xyz="1 0 0" />
    <limit effort="2" lower="-0.261799387799" upper="1.57079632679" velocity="2.0" />
    <dynamics damping="0.1" />
  </joint>
  <link name="rfmiddle">
    <inertial>
      <origin rpy="0.0 0.0 1.570494235572534" xyz="0 0 0.012" />
      <mass value="0.012" />
      <inertia ixx="1e-05" ixy="0.0" ixz="0.0" iyy="1e-05" iyz="0.0" izz="1e-05" />
    </inertial>
    <visual>
      <origin rpy="0 0 0" xyz="0 0 0" />
      <geometry name="rfmiddle_visual">
        <mesh filename="meshes/visual/f_middle_E3M5.obj" scale="0.001 0.001 0.001" />
      </geometry>
    </visual>
    <collision>
      <origin rpy="0 0 0" xyz="0 0 0.0125" />
      <geometry name="rfmiddle_collision_geom">
        <cylinder length="0.025" radius="0.007" />
      </geometry>
    </collision>
    <collision>
      <origin rpy="0 0 0" xyz="0 0 0.0" />
      <geometry>
        <sphere radius="0.007" />
      </geometry>
    </collision>
    <collision>
      <origin rpy="0 0 0" xyz="0 0 0.025" />
      <geometry>
        <sphere radius="0.007" />
      </geometry>
    </collision>
  </link>
  <joint name="RFJ2" type="revolute">
    <parent link="rfproximal" />
    <child link="rfmiddle" />
    <origin rpy="0 0 0" xyz="0 0 0.045" />
    <axis xyz="1 0 0" />
    <limit effort="2" lower="0" upper="1.57079632679" velocity="2.0" />
    <dynamics damping="0.1" />
  </joint>
  <link name="rfdistal">
    
    <inertial>
      <mass value="0.01" />
      <origin xyz="0 0 0.015" rpy="0.0 0.008484101780550713 1.5705122358934482" />
      <inertia ixx="1e-05" ixy="0.0" ixz="0.0" iyy="1e-05" iyz="0.0" izz="1e-05" />
    </inertial>
    <visual>
      <origin rpy="0 0 0" xyz="0 0 0" />
      <geometry name="rfdistal_visual">
        <mesh filename="meshes/visual/f_distal_pst.obj" scale="0.001 0.001 0.001" />
      </geometry>
    </visual>
    <collision>
      <origin rpy="0 0 0" xyz="0 0 0" />
      <geometry name="rfdistal_collision_geom">
        <mesh filename="meshes/collision/f_distal_pst.obj" scale="0.001 0.001 0.001" />
      </geometry>
    </collision>
  </link>
  <joint name="RFJ1" type="revolute">
    <parent link="rfmiddle" />
    <child link="rfdistal" />
    <origin rpy="0 0 0" xyz="0 0 0.025" />
    <axis xyz="1 0 0" />
    
    <limit effort="2" lower="0" upper="1.57079632679" velocity="2.0" />
    <dynamics damping="0.1" />
  </joint>
  <link name="rftip">
    <inertial>
      <mass value="0.001" />
      <inertia ixx="0.0" ixy="0.0" ixz="0.0" iyy="0.0" iyz="0.0" izz="0.0" />
    </inertial>
  </link>
  <joint name="RFtip" type="fixed">
    <parent link="rfdistal" />
    <child link="rftip" />
    <origin rpy="0 0 0" xyz="0 0 0.026" />
  </joint>
  <link name="lfmetacarpal">
    <inertial>
      <origin rpy="-0.22009092437605474 0.03873968912491095 1.5475360912392935" xyz="-0.014 0.001 0.014" />
      <mass value="0.075" />
      <inertia ixx="1e-05" ixy="0.0" ixz="0.0" iyy="1e-05" iyz="0.0" izz="1e-05" />
    </inertial>
    <visual>
      <origin rpy="0 0.9599 0" xyz="0 0 0" />
      <geometry name="lfmetacarpal_visual">
        <mesh filename="meshes/visual/lf_metacarpal_E3M5.obj" scale="0.001 0.001 0.001" />
      </geometry>
    </visual>
    <collision>
      <origin rpy="0 0.9599 0" xyz="0.026986375 0 0.019" />
      <geometry name="lfmetacarpal_collision_geom">
        <box size="0.018 0.024 0.040" />
      </geometry>
    </collision>
  </link>
  <joint name="LFJ5" type="revolute">
    <parent link="palm" />
    <child link="lfmetacarpal" />
    <origin rpy="0 -0.9599 0" xyz="-0.033 0 0.02071" />
    <axis xyz="1 0 0" />
    <limit effort="2" lower="0" upper="0.785398163397" velocity="2.0" />
    <dynamics damping="0.1" />
  </joint>
  <link name="lfknuckle">
    <inertial>
      <origin rpy="2.047545928289858 0.011364244606314553 0.007128520828102848" xyz="0 0 0" />
      <mass value="0.008" />
      <inertia ixx="1e-05" ixy="0.0" ixz="0.0" iyy="1e-05" iyz="0.0" izz="1e-05" />
    </inertial>
    <visual>
      <origin rpy="0 0 0" xyz="0 0 0.0005" />
      <geometry name="lfknuckle_visual">
        <mesh filename="meshes/visual/f_knuckle_E3M5.obj" scale="0.001 0.001 0.001" />
      </geometry>
    </visual>
    <collision>
      <geometry name="ffknuckle_visual">
        <mesh filename="meshes/collision/f_knuckle_E3M5.obj" />
      </geometry>
    </collision>
  </link>
  <joint name="LFJ4" type="revolute">
    <parent link="lfmetacarpal" />
    <child link="lfknuckle" />
    
    <origin rpy="0 0.9599 0" xyz="0.05397275 0 0.03779463" />
    <axis xyz="0 1 0" />
    <limit effort="2" lower="-0.349065850399" upper="0.349065850399" velocity="2.0" />
    <dynamics damping="0.1" />
  </joint>
  <link name="lfproximal">
    <inertial>
      <mass value="0.014" />
      <origin xyz="0 0 0.023" rpy="0.0 0.01131224126368007 1.570526236591334" />
      <inertia ixx="1e-05" ixy="0.0" ixz="0.0" iyy="1e-05" iyz="0.0" izz="1e-05" />
    </inertial>
    <visual>
      <origin rpy="0 0 0" xyz="0 0 0" />
      <geometry name="lfproximal_visual">
        <mesh filename="meshes/visual/f_proximal_E3M5.obj" scale="0.001 0.001 0.001" />
      </geometry>
    </visual>
    <collision>
      <origin rpy="0 0 0" xyz="0 0 0.025" />
      <geometry name="lfproximal_collision_geom">
        <cylinder length="0.040" radius="0.007" />
      </geometry>
    </collision>
  </link>
  <joint name="LFJ3" type="revolute">
    <parent link="lfknuckle" />
    <child link="lfproximal" />
    <origin rpy="0 0 0" xyz="0 0 0" />
    <axis xyz="1 0 0" />
    <limit effort="2" lower="-0.261799387799" upper="1.57079632679" velocity="2.0" />
    <dynamics damping="0.1" />
  </joint>
  <link name="lfmiddle">
    <inertial>
      <origin rpy="0.0 0.0 1.570494235572534" xyz="0 0 0.012" />
      <mass value="0.012" />
      <inertia ixx="1e-05" ixy="0.0" ixz="0.0" iyy="1e-05" iyz="0.0" izz="1e-05" />
    </inertial>
    <visual>
      <origin rpy="0 0 0" xyz="0 0 0" />
      <geometry name="lfmiddle_visual">
        <mesh filename="meshes/visual/f_middle_E3M5.obj" scale="0.001 0.001 0.001" />
      </geometry>
    </visual>
    <collision>
      <origin rpy="0 0 0" xyz="0 0 0.0125" />
      <geometry name="lfmiddle_collision_geom">
        <cylinder length="0.025" radius="0.007" />
      </geometry>
    </collision>
    <collision>
      <origin rpy="0 0 0" xyz="0 0 0.0" />
      <geometry>
        <sphere radius="0.007" />
      </geometry>
    </collision>
    <collision>
      <origin rpy="0 0 0" xyz="0 0 0.025" />
      <geometry>
        <sphere radius="0.007" />
      </geometry>
    </collision>
  </link>
  <joint name="LFJ2" type="revolute">
    <parent link="lfproximal" />
    <child link="lfmiddle" />
    <origin rpy="0 0 0" xyz="0 0 0.045" />
    <axis xyz="1 0 0" />
    <limit effort="2" lower="0" upper="1.57079632679" velocity="2.0" />
    <dynamics damping="0.1" />
  </joint>
  <link name="lfdistal">
    
    <inertial>
      <mass value="0.01" />
      <origin xyz="0 0 0.015" rpy="0.0 0.008484101780550713 1.5705122358934482" />
      <inertia ixx="1e-05" ixy="0.0" ixz="0.0" iyy="1e-05" iyz="0.0" izz="1e-05" />
    </inertial>
    <visual>
      <origin rpy="0 0 0" xyz="0 0 0" />
      <geometry name="lfdistal_visual">
        <mesh filename="meshes/visual/f_distal_pst.obj" scale="0.001 0.001 0.001" />
      </geometry>
    </visual>
    <collision>
      <origin rpy="0 0 0" xyz="0 0 0" />
      <geometry name="lfdistal_collision_geom">
        <mesh filename="meshes/collision/f_distal_pst.obj" scale="0.001 0.001 0.001" />
      </geometry>
    </collision>
  </link>
  <joint name="LFJ1" type="revolute">
    <parent link="lfmiddle" />
    <child link="lfdistal" />
    <origin rpy="0 0 0" xyz="0 0 0.025" />
    <axis xyz="1 0 0" />
    
    <limit effort="2" lower="0" upper="1.57079632679" velocity="2.0" />
    <dynamics damping="0.1" />
  </joint>
  <link name="lftip">
    <inertial>
      <mass value="0.001" />
      <inertia ixx="0.0" ixy="0.0" ixz="0.0" iyy="0.0" iyz="0.0" izz="0.0" />
    </inertial>
  </link>
  <joint name="LFtip" type="fixed">
    <parent link="lfdistal" />
    <child link="lftip" />
    <origin rpy="0 0 0" xyz="0 0 0.026" />
  </joint>
  <link name="thbase">
    <inertial>
      <mass value="0.01" />
      <origin rpy="0 0 0" xyz="0 0 0" />
      <inertia ixx="1e-05" ixy="0.0" ixz="0.0" iyy="1e-05" iyz="0.0" izz="1e-05" />
    </inertial>
    <visual>
      <origin rpy="0 0 0" xyz="0 0 0" />
      <geometry name="thbase_visual">
        <box size="0.001 0.001 0.001" />
      </geometry>
    </visual>
    <collision>
      <origin rpy="0 0 0" xyz="0 0 0" />
      <geometry name="thbase_collision_geom">
        <sphere radius="0.011" />
      </geometry>
    </collision>
  </link>
  <joint name="THJ5" type="revolute">
    <parent link="palm" />
    <child link="thbase" />
    <origin rpy="-0.785398163397 0 -1.57079632679" xyz="0.034 -0.00858 0.029" />
    <axis xyz="0 0 -1" />
    <limit effort="5.0" lower="-1.0471975512" upper="1.0471975512" velocity="4.0" />
    <dynamics damping="0.2" />
  </joint>
  <link name="thproximal">
    <inertial>
      <mass value="0.016" />
      <origin rpy="0.00038200074542042885 0.001964001262623749 0.3845075233557715" xyz="0 0 0.017" />
      <inertia ixx="1e-05" ixy="0.0" ixz="0.0" iyy="1e-05" iyz="0.0" izz="1e-05" />
    </inertial>
    <visual>
      <origin rpy="0 0 1.57079632679" xyz="0 0 0" />
      <geometry name="thproximal_visual">
        <mesh filename="meshes/visual/th_proximal_E3M5.obj" scale="0.001 0.001 0.001" />
      </geometry>
    </visual>
    <collision>
      <geometry name="thproximal_collision">
        <mesh filename="meshes/collision/th_proximal_E3M5.obj" scale="0.001 0.001 0.001" />
      </geometry>
    </collision>
  </link>
  <joint name="THJ4" type="revolute">
    <parent link="thbase" />
    <child link="thproximal" />
    <origin rpy="0 0 0" xyz="0 0 0" />
    <axis xyz="0 1 0" />
    <limit effort="3" lower="0.0" upper="1.2217304764" velocity="4.0" />
    <dynamics damping="0.2" />
  </joint>
  <link name="thhub">
    <inertial>
      <mass value="0.002" />
      <origin rpy="0 0 0" xyz="0 0 0" />
      <inertia ixx="1e-05" ixy="0.0" ixz="0.0" iyy="1e-05" iyz="0.0" izz="1e-05" />
    </inertial>
    <collision>
      <origin rpy="0 0 0" xyz="0 0 0" />
      <geometry name="thhub_collision_geom">
        <sphere radius="0.010" />
      </geometry>
    </collision>
  </link>
  <joint name="THJ3" type="revolute">
    <parent link="thproximal" />
    <child link="thhub" />
    <origin rpy="0 0 0" xyz="0 0 0.038" />
    <axis xyz="0 1 0" />
    <limit effort="2.0" lower="-0.209439510239" upper="0.209439510239" velocity="4.0" />
    <dynamics damping="0.2" />
  </joint>
  <link name="thmiddle">
    <inertial>
      <mass value="0.016" />
      <origin rpy="-0.0020422013813581478 -0.013994456785840428 0.006014625176093502" xyz="0 0 0.016" />
      <inertia ixx="1e-05" ixy="0.0" ixz="0.0" iyy="1e-05" iyz="0.0" izz="1e-05" />
    </inertial>
    <visual>
      <origin rpy="0 0 1.57079632679" xyz="0 0 0" />
      <geometry name="thmiddle_visual">
        <mesh filename="meshes/visual/th_middle_E3M5.obj" scale="0.001 0.001 0.001" />
      </geometry>
    </visual>
    <collision>
      <geometry name="thmiddle_collision">
        <mesh filename="meshes/collision/th_middle_E3M5.obj" scale="0.001 0.001 0.001" />
      </geometry>
    </collision>
  </link>
  <joint name="THJ2" type="revolute">
    <parent link="thhub" />
    <child link="thmiddle" />
    <origin rpy="0 0 0" xyz="0 0 0" />
    <axis xyz="1 0 0" />
    <limit effort="2.0" lower="-0.698131700798" upper="0.698131700798" velocity="2.0" />
    <dynamics damping="0.1" />
  </joint>
  
  <link name="thdistal">
    
    <inertial>
      <mass value="0.016" />
      <origin rpy="-0.010506558414807786 -0.09399434455500061 0.010506558414807786" xyz="0 0 0.016" />
      <inertia ixx="1e-05" ixy="0.0" ixz="0.0" iyy="1e-05" iyz="0.0" izz="1e-05" />
    </inertial>
    <visual>
      <origin rpy="0 0 0" xyz="0 0 0" />
      <geometry name="thdistal_visual">
        <mesh filename="meshes/visual/th_distal_pst.obj" scale="0.001 0.001 0.001" />
      </geometry>
    </visual>
    <collision>
      <origin rpy="0 0 0" xyz="0 0 0" />
      <geometry name="thmiddle_collision_geom">
        <mesh filename="meshes/visual/th_distal_pst.obj" scale="0.001 0.001 0.001" />
      </geometry>
    </collision>
  </link>
  <joint name="THJ1" type="revolute">
    <parent link="thmiddle" />
    <child link="thdistal" />
    <origin rpy="0 0 0" xyz="0 0 0.032" />
    <axis xyz="1 0 0" />
    <limit effort="1.0" lower="-0.261799387799" upper="1.57079632679" velocity="4.0" />
    <dynamics damping="0.2" />
  </joint>
  <link name="thtip">
    <inertial>
      <mass value="0.001" />
      <inertia ixx="0.0" ixy="0.0" ixz="0.0" iyy="0.0" iyz="0.0" izz="0.0" />
    </inertial>
  </link>
  <joint name="THtip" type="fixed">
    <parent link="thdistal" />
    <child link="thtip" />
    <origin rpy="0 0 0" xyz="0 0 0.0275" />
  </joint>
</robot>